<?xml version="1.0" ?>
<!-- =================================================================================== -->
<!-- |    This document was autogenerated by xacro from turtle.urdf.xacro              | -->
<!-- |    EDITING THIS FILE BY HAND IS NOT RECOMMENDED                                 | -->
<!-- =================================================================================== -->
<robot name="dfrobot_turtle">
  <material name="black">
    <color rgba="0 0 0 1"/>
  </material>
  <material name="yellow">
    <color rgba="1 1 0 1"/>
  </material>
  <material name="green">
    <color rgba="0 0.5 0 1"/>
  </material>
  <material name="silver">
    <color rgba="0.75 0.75 0.75 1"/>
  </material>
  <material name="rubber">
    <color rgba="0.15 0.15 0.15 1"/>
  </material>
  <material name="red">
    <color rgba="1 0 0 1"/>
</material>
  
   <joint name="laser_joint" type="fixed">
        <parent link="control_board"/>
        <child link="laser_frame"/>
        <origin xyz="0.025 0 0.025" rpy="0 0 0"/>
    </joint>

    <link name="laser_frame">
        <visual>
        <geometry>
            <cylinder radius="0.1" length="0.055"/>
        </geometry>
        <material name="red"/>
    </visual>
    <collision>
        <geometry>
            <cylinder radius="0.1" length="0.055"/>
        </geometry>
    </collision>
    
    </link>
  <gazebo reference="laser_frame">
    <material>Gazebo/Red</material>
    <sensor name="laser" type="ray">
    <pose> 0 0 0 0 0 0 </pose>
    <visualize>true</visualize>
    <update_rate>10</update_rate>
    <ray>  
    <scan>
        <horizontal>
            <samples>360</samples>
            <min_angle>-3.14</min_angle>
            <max_angle>3.14</max_angle>
        </horizontal>
    </scan>
    <range>
        <min>0.15</min>
        <max>12</max>
    </range>     
    </ray>
    <plugin name="laser_controller" filename="libgazebo_ros_ray_sensor.so">
    <ros>
        <argument>--remap ~/out:=scan</argument>
    </ros>
    <output_type>sensor_msgs/LaserScan</output_type>
    <frame_name>laser_frame</frame_name>
    </plugin>
</sensor>
</gazebo>
  <!-- Control board -->
  <link name="control_board">
    <visual>
      <geometry>
        <box size="0.08 0.1 0.001"/>
      </geometry>
      <material name="green"/>
    </visual>
    <inertial>
      <mass value="0.1"/>
      <inertia ixx="1e-6" ixy="0" ixz="0" iyy="1e-6" iyz="0" izz="1e-6"/>
    </inertial>
  </link>
  <gazebo reference="control_board">
    <material>Gazebo/Green</material>
  </gazebo>
  <!-- ros_control plugin -->
  
  <gazebo>
      <plugin filename="libgazebo_ros_diff_drive.so" name="gazebo_base_controller">
        <odometry_frame>odom</odometry_frame>
        <commandTopic>cmd_vel</commandTopic>
        <publish_odom>true</publish_odom>
        <publish_odom_tf>true</publish_odom_tf>
        <update_rate>15.0</update_rate>
        <left_joint>base_to_wheel_left_joint</left_joint>
        <right_joint>base_to_wheel_right_joint</right_joint>
        <wheel_separation>0.145</wheel_separation>
        <wheel_diameter>0.065</wheel_diameter>
        <max_wheel_acceleration>0.7</max_wheel_acceleration>
        <robotBaseFrame>base_link</robotBaseFrame>
  
      </plugin>
    </gazebo>
    
  <link name="base_link">
    <visual>
      <geometry>
        <cylinder length="0.055" radius="0.085"/>
      </geometry>
      <material name="black"/>
    </visual>
    <collision>
      <geometry>
        <cylinder length="0.055" radius="0.085"/>
      </geometry>
    </collision>
    
    <inertial>
      <mass value="0.3"/>
      <inertia ixx="0.01" ixy="0.0" ixz="0.0" iyy="0.01" iyz="0.0" izz="0.01"/>
    </inertial>
  
  </link>
  <gazebo reference="base_link">
    <material>Gazebo/Black</material>
  </gazebo>
  <joint name="controlboard_to_base_joint" type="fixed">
    <parent link="base_link"/>
    <child link="control_board"/>
    <origin rpy="0 0 0" xyz="-0.03 0 0.0295"/>
  </joint>
  <link name="wheel_right">
    <visual>
      <geometry>
        <cylinder length="0.025" radius="0.0325"/>
      </geometry>
      <material name="rubber"/>
    </visual>
    <collision>
      <geometry>
        <cylinder length="0.025" radius="0.0325"/>
      </geometry>
    </collision>
    <inertial>
      <mass value="0.2"/>
      <inertia ixx="1e-6" ixy="0" ixz="0" iyy="1e-6" iyz="0" izz="1e-6"/>
    </inertial>
  </link>
  <gazebo reference="wheel_right">
    <mu1 value="200.0"/>
    <mu2 value="100.0"/>
    <kp value="10000000.0"/>
    <kd value="1.0"/>
    <material>Gazebo/DarkGrey</material>
  </gazebo>
  <joint name="base_to_wheel_right_joint" type="continuous">
    <parent link="base_link"/>
    <child link="wheel_right"/>
    <axis xyz="0 0 1"/>
    <origin rpy="-1.5707963267948966  0 0" xyz="-0.025 -0.07250000000000001 -0.02"/>
  </joint>
  <!-- ros_control plugin 
  <transmission name="wheel_right_trans">
    <type>transmission_interface/SimpleTransmission</type>
    <actuator name="wheel_right_motor">
      <mechanicalReduction>1</mechanicalReduction>
    </actuator>
    <joint name="base_to_wheel_right_joint">
      <hardwareInterface>hardware_interface/VelocityJointInterface</hardwareInterface>
    </joint>
  </transmission>
  -->
  <link name="wheel_rim_right">
    <visual>
      <geometry>
        <cylinder length="0.026000000000000002" radius="0.025"/>
      </geometry>
      <material name="yellow"/>
    </visual>
    <inertial>
      <mass value="0.1"/>
      <inertia ixx="1e-6" ixy="0" ixz="0" iyy="1e-6" iyz="0" izz="1e-6"/>
    </inertial>
  </link>
  <gazebo reference="wheel_rim_right">
    <material>Gazebo/Yellow</material>
  </gazebo>
  <joint name="wheel_right_to_rim_joint" type="fixed">
    <parent link="wheel_right"/>
    <child link="wheel_rim_right"/>
    <origin rpy="0 0 0" xyz="0 0 0"/>
  </joint>
  

  <link name="wheel_left">
    <visual>
      <geometry>
        <cylinder length="0.025" radius="0.0325"/>
      </geometry>
      <material name="rubber"/>
    </visual>
    <collision>
      <geometry>
        <cylinder length="0.025" radius="0.0325"/>
      </geometry>
    </collision>
    <inertial>
      <mass value="0.2"/>
      <inertia ixx="1e-6" ixy="0" ixz="0" iyy="1e-6" iyz="0" izz="1e-6"/>
    </inertial>
  </link>
  <gazebo reference="wheel_left">
    <mu1 value="200.0"/>
    <mu2 value="100.0"/>
    <kp value="10000000.0"/>
    <kd value="1.0"/>
    <material>Gazebo/DarkGrey</material>
  </gazebo>
  <joint name="base_to_wheel_left_joint" type="continuous">
    <parent link="base_link"/>
    <child link="wheel_left"/>
    <axis xyz="0 0 1"/>
    <origin rpy="-1.5707963267948966 0 0" xyz="-0.025 0.07250000000000001    -0.02"/>
  </joint>

  <!-- 
  <transmission name="wheel_left_trans">
    <type>transmission_interface/SimpleTransmission</type>
    <actuator name="wheel_left_motor">
      <mechanicalReduction>1</mechanicalReduction>
    </actuator>
    <joint name="base_to_wheel_left_joint">
      <hardwareInterface>hardware_interface/VelocityJointInterface</hardwareInterface>
    </joint>
  </transmission>
  
-->
  <link name="wheel_rim_left">
    <visual>
      <geometry>
        <cylinder length="0.026000000000000002" radius="0.025"/>
      </geometry>
      <material name="yellow"/>
    </visual>
    <inertial>
      <mass value="0.1"/>
      <inertia ixx="1e-6" ixy="0" ixz="0" iyy="1e-6" iyz="0" izz="1e-6"/>
    </inertial>
  </link>
  <gazebo reference="wheel_rim_left">
    <material>Gazebo/Yellow</material>
  </gazebo>
  <joint name="wheel_left_to_rim_joint" type="fixed">
    <parent link="wheel_left"/>
    <child link="wheel_rim_left"/>
    <origin rpy="0 0 0" xyz="0 0 0"/>
  </joint>
  
  <link name="caster_housing">
    <visual>
      <geometry>
        <cylinder length="0.01" radius="0.01"/>
      </geometry>
      <material name="silver"/>
    </visual>
    <collision>
      <geometry>
        <cylinder length="0.01" radius="0.01"/>
      </geometry>
    </collision>
    <inertial>
      <mass value="0.1"/>
      <inertia ixx="1e-6" ixy="0" ixz="0" iyy="1e-6" iyz="0" izz="1e-6"/>
    </inertial>
  </link>
  <gazebo reference="caster_housing">
    <material>Gazebo/Grey</material>
  </gazebo>
  <joint name="base_to_caster_housing_joint" type="fixed">
    <parent link="base_link"/>
    <child link="caster_housing"/>
    <origin rpy="0 0 0" xyz="0.07 0 -0.0325"/>
  </joint>
  <link name="caster_ball">
    <visual>
      <geometry>
        <sphere radius="0.01"/>
      </geometry>
      <material name="silver"/>
    </visual>
    <collision>
      <geometry>
        <sphere radius="0.01"/>
      </geometry>
    </collision>
    <inertial>
      <mass value="0.1"/>
      <inertia ixx="1e-6" ixy="0" ixz="0" iyy="1e-6" iyz="0" izz="1e-6"/>
    </inertial>
  </link>
  <gazebo reference="caster_ball">
    <material>Gazebo/Grey</material>
  </gazebo>
  <joint name="base_to_caster_ball_joint" type="continuous">
    <parent link="caster_housing"/>
    <child link="caster_ball"/>
    <axis xyz="0 1 0"/>
    <origin rpy="0 0 0" xyz="0 0 -0.005"/>
  </joint>
</robot>
